Workbook

Sheet Class Prep
A1: Alkhidmat School, Mannan & Qazi Campus, Hala
A2: Mid Term Examination 2025-26
A3: General Information - Class Prep | D3: Consolidated Result Sheet | K3: Aggregate
A4: Sr # | B4: Aghosh ID | C4: Name of Student | D4: Eng | E4: Urdu | F4: Maths | G4: Islam/GK | H4: Art | I4: Total | J4: Secured Marks | K4: % | L4: Remarks
D5: 100 | E5: 100 | F5: 100 | G5: 100 | H5: 100 | I5: =SUM(D5:H5) -> 500
A6: 1 | B6: AAH- 221 | C6: Ali | D6: 88 | E6: 94 | F6: 88 | G6: 84 | H6: 87 | I6: 500 | J6: =SUM(D6:H6) -> 441 | K6: =J6/I5 -> 0.882 | L6: =IF(K6>=85%,"Outstanding",IF(K6>=80%,"Excellent",IF(K6>=70%,"Very Good",IF(K6>=60%,"Good",IF(K6>=50%,"Satisfactory",IF(K6>=40%,"Fair","Needs Attention")))))) -> Outstanding
A7: 2 | B7: AAH- 222 | C7: Ali Ahmed | D7: 86 | E7: 12 | F7: 12 | G7: 23 | H7: 43 | I7: 500 | J7: =SUM(D7:H7) -> 176 | K7: =J7/I6 -> 0.352 | L7: =IF(K7>=85%,"Outstanding",IF(K7>=80%,"Excellent",IF(K7>=70%,"Very Good",IF(K7>=60%,"Good",IF(K7>=50%,"Satisfactory",IF(K7>=40%,"Fair","Needs Attention")))))) -> Needs Attention
A8: 3 | I8: 500 | J8: =SUM(D8:H8) -> 0 | K8: =J8/I7 -> 0 | L8: =IF(K8>=85%,"Outstanding",IF(K8>=80%,"Excellent",IF(K8>=70%,"Very Good",IF(K8>=60%,"Good",IF(K8>=50%,"Satisfactory",IF(K8>=40%,"Fair","Needs Attention")))))) -> Needs Attention
A9: 4 | I9: 500 | J9: =SUM(D9:H9) -> 0 | K9: =J9/I8 -> 0 | L9: =IF(K9>=85%,"Outstanding",IF(K9>=80%,"Excellent",IF(K9>=70%,"Very Good",IF(K9>=60%,"Good",IF(K9>=50%,"Satisfactory",IF(K9>=40%,"Fair","Needs Attention")))))) -> Needs Attention
A10: 5 | I10: 500 | J10: =SUM(D10:H10) -> 0 | K10: =J10/I9 -> 0 | L10: =IF(K10>=85%,"Outstanding",IF(K10>=80%,"Excellent",IF(K10>=70%,"Very Good",IF(K10>=60%,"Good",IF(K10>=50%,"Satisfactory",IF(K10>=40%,"Fair","Needs Attention")))))) -> Needs Attention
A11: 6 | I11: 500 | J11: =SUM(D11:H11) -> 0 | K11: =J11/I10 -> 0 | L11: =IF(K11>=85%,"Outstanding",IF(K11>=80%,"Excellent",IF(K11>=70%,"Very Good",IF(K11>=60%,"Good",IF(K11>=50%,"Satisfactory",IF(K11>=40%,"Fair","Needs Attention")))))) -> Needs Attention
A12: 7 | I12: 500 | J12: =SUM(D12:H12) -> 0 | K12: =J12/I11 -> 0 | L12: =IF(K12>=85%,"Outstanding",IF(K12>=80%,"Excellent",IF(K12>=70%,"Very Good",IF(K12>=60%,"Good",IF(K12>=50%,"Satisfactory",IF(K12>=40%,"Fair","Needs Attention")))))) -> Needs Attention
A13: 8 | I13: 500 | J13: =SUM(D13:H13) -> 0 | K13: =J13/I12 -> 0 | L13: =IF(K13>=85%,"Outstanding",IF(K13>=80%,"Excellent",IF(K13>=70%,"Very Good",IF(K13>=60%,"Good",IF(K13>=50%,"Satisfactory",IF(K13>=40%,"Fair","Needs Attention")))))) -> Needs Attention
A14: 9 | I14: 500 | J14: =SUM(D14:H14) -> 0 | K14: =J14/I13 -> 0 | L14: =IF(K14>=85%,"Outstanding",IF(K14>=80%,"Excellent",IF(K14>=70%,"Very Good",IF(K14>=60%,"Good",IF(K14>=50%,"Satisfactory",IF(K14>=40%,"Fair","Needs Attention")))))) -> Needs Attention
A15: 10 | I15: 500 | J15: =SUM(D15:H15) -> 0 | K15: =J15/I14 -> 0 | L15: =IF(K15>=85%,"Outstanding",IF(K15>=80%,"Excellent",IF(K15>=70%,"Very Good",IF(K15>=60%,"Good",IF(K15>=50%,"Satisfactory",IF(K15>=40%,"Fair","Needs Attention")))))) -> Needs Attention
A16: 11 | I16: 500 | J16: =SUM(D16:H16) -> 0 | K16: =J16/I15 -> 0 | L16: =IF(K16>=85%,"Outstanding",IF(K16>=80%,"Excellent",IF(K16>=70%,"Very Good",IF(K16>=60%,"Good",IF(K16>=50%,"Satisfactory",IF(K16>=40%,"Fair","Needs Attention")))))) -> Needs Attention
A17: 12 | I17: 500 | J17: =SUM(D17:H17) -> 0 | K17: =J17/I16 -> 0 | L17: =IF(K17>=85%,"Outstanding",IF(K17>=80%,"Excellent",IF(K17>=70%,"Very Good",IF(K17>=60%,"Good",IF(K17>=50%,"Satisfactory",IF(K17>=40%,"Fair","Needs Attention")))))) -> Needs Attention
A18: 13 | I18: 500 | J18: =SUM(D18:H18) -> 0 | K18: =J18/I17 -> 0 | L18: =IF(K18>=85%,"Outstanding",IF(K18>=80%,"Excellent",IF(K18>=70%,"Very Good",IF(K18>=60%,"Good",IF(K18>=50%,"Satisfactory",IF(K18>=40%,"Fair","Needs Attention")))))) -> Needs Attention
A19: 14 | I19: 500 | J19: =SUM(D19:H19) -> 0 | K19: =J19/I18 -> 0 | L19: =IF(K19>=85%,"Outstanding",IF(K19>=80%,"Excellent",IF(K19>=70%,"Very Good",IF(K19>=60%,"Good",IF(K19>=50%,"Satisfactory",IF(K19>=40%,"Fair","Needs Attention")))))) -> Needs Attention
A20: 15 | I20: 500 | J20: =SUM(D20:H20) -> 0 | K20: =J20/I19 -> 0 | L20: =IF(K20>=85%,"Outstanding",IF(K20>=80%,"Excellent",IF(K20>=70%,"Very Good",IF(K20>=60%,"Good",IF(K20>=50%,"Satisfactory",IF(K20>=40%,"Fair","Needs Attention")))))) -> Needs Attention
A22: ________________________ Principal | H22: ____________________ Class Teacher | K22: Summary Grade Prep
K23: No. of Students | L23: 0
K24: Appeared | L24: 0
C25: Subjects | D25: English | E25: Urdu | F25: Maths | G25: Islam/GK | H25: Art | K25: Pass | L25: 0
C26: Pass (>=40%) | D26: 0 | E26: 0 | F26: 0 | G26: 0 | H26: 0 | K26: % Pass | L26: 0
C27: Pass% | D27: 0 | E27: 0 | F27: 0 | G27: 0 | H27: 0 | K27: Unsuccessful | L27: 0
C28: Fail | D28: 0 | E28: 0 | F28: 0 | G28: 0 | H28: 0 | K28: % Unsuccessful | L28: 0
C29: Fail % | D29: 0 | E29: 0 | F29: 0 | G29: 0 | H29: 0

Sheet Class I
A1: Alkhidmat School, Mannan & Qazi Campus, Hala
A2: Mid Term Examination 2025-26
A3: General Information - Grade I | D3: Consolidated Result Sheet | K3: Aggregate
A4: Sr # | B4: Aghosh ID | C4: Name of Student | D4: Eng | E4: Urdu | F4: GK | G4: Maths | H4: Comp | I4: Islam | J4: Sindhi | K4: Total | L4: Secured Marks | M4: % | N4: Remarks
D5: 100 | E5: 100 | F5: 100 | G5: 100 | H5: Grades | I5: 50 | J5: 50 | K5: =SUM(D5:J5) -> 500
A6: 1 | B6: AAH- 220 | C6: Shayan | D6: 88 | E6: 94 | F6: 88 | G6: 84 | H6: B | I6: 43 | J6: 39 | K6: 500 | L6: =SUM(D6:J6) -> 436 | M6: =L6/K5 -> 0.872 | N6: =IF(M6>=85%,"Outstanding",IF(M6>=80%,"Excellent",IF(M6>=70%,"Very Good",IF(M6>=60%,"Good",IF(M6>=50%,"Satisfactory",IF(M6>=40%,"Fair","Needs Attention")))))) -> Outstanding
A7: 2 | K7: 500 | L7: =SUM(D7:J7) -> 0 | M7: =L7/K6 -> 0 | N7: =IF(M7>=85%,"Outstanding",IF(M7>=80%,"Excellent",IF(M7>=70%,"Very Good",IF(M7>=60%,"Good",IF(M7>=50%,"Satisfactory",IF(M7>=40%,"Fair","Needs Attention")))))) -> Needs Attention
A8: 3 | K8: 500 | L8: =SUM(D8:J8) -> 0 | M8: =L8/K7 -> 0 | N8: =IF(M8>=85%,"Outstanding",IF(M8>=80%,"Excellent",IF(M8>=70%,"Very Good",IF(M8>=60%,"Good",IF(M8>=50%,"Satisfactory",IF(M8>=40%,"Fair","Needs Attention")))))) -> Needs Attention
A9: 4 | K9: 500 | L9: =SUM(D9:J9) -> 0 | M9: =L9/K8 -> 0 | N9: =IF(M9>=85%,"Outstanding",IF(M9>=80%,"Excellent",IF(M9>=70%,"Very Good",IF(M9>=60%,"Good",IF(M9>=50%,"Satisfactory",IF(M9>=40%,"Fair","Needs Attention")))))) -> Needs Attention
A10: 5 | K10: 500 | L10: =SUM(D10:J10) -> 0 | M10: =L10/K9 -> 0 | N10: =IF(M10>=85%,"Outstanding",IF(M10>=80%,"Excellent",IF(M10>=70%,"Very Good",IF(M10>=60%,"Good",IF(M10>=50%,"Satisfactory",IF(M10>=40%,"Fair","Needs Attention")))))) -> Needs Attention
A11: 6 | K11: 500 | L11: =SUM(D11:J11) -> 0 | M11: =L11/K10 -> 0 | N11: =IF(M11>=85%,"Outstanding",IF(M11>=80%,"Excellent",IF(M11>=70%,"Very Good",IF(M11>=60%,"Good",IF(M11>=50%,"Satisfactory",IF(M11>=40%,"Fair","Needs Attention")))))) -> Needs Attention
A12: 7 | K12: 500 | L12: =SUM(D12:J12) -> 0 | M12: =L12/K11 -> 0 | N12: =IF(M12>=85%,"Outstanding",IF(M12>=80%,"Excellent",IF(M12>=70%,"Very Good",IF(M12>=60%,"Good",IF(M12>=50%,"Satisfactory",IF(M12>=40%,"Fair","Needs Attention")))))) -> Needs Attention
A13: 8 | K13: 500 | L13: =SUM(D13:J13) -> 0 | M13: =L13/K12 -> 0 | N13: =IF(M13>=85%,"Outstanding",IF(M13>=80%,"Excellent",IF(M13>=70%,"Very Good",IF(M13>=60%,"Good",IF(M13>=50%,"Satisfactory",IF(M13>=40%,"Fair","Needs Attention")))))) -> Needs Attention
A14: 9 | K14: 500 | L14: =SUM(D14:J14) -> 0 | M14: =L14/K14 -> 0 | N14: =IF(M14>=85%,"Outstanding",IF(M14>=80%,"Excellent",IF(M14>=70%,"Very Good",IF(M14>=60%,"Good",IF(M14>=50%,"Satisfactory",IF(M14>=40%,"Fair","Needs Attention")))))) -> Needs Attention
A15: 10 | K15: 500 | L15: =SUM(D15:J15) -> 0 | M15: =L15/K14 -> 0 | N15: =IF(M15>=85%,"Outstanding",IF(M15>=80%,"Excellent",IF(M15>=70%,"Very Good",IF(M15>=60%,"Good",IF(M15>=50%,"Satisfactory",IF(M15>=40%,"Fair","Needs Attention")))))) -> Needs Attention
A16: 11 | K16: 500 | L16: =SUM(D16:J16) -> 0 | M16: =L16/K15 -> 0 | N16: =IF(M16>=85%,"Outstanding",IF(M16>=80%,"Excellent",IF(M16>=70%,"Very Good",IF(M16>=60%,"Good",IF(M16>=50%,"Satisfactory",IF(M16>=40%,"Fair","Needs Attention")))))) -> Needs Attention
A17: 12 | K17: 500 | L17: =SUM(D17:J17) -> 0 | M17: =L17/K16 -> 0 | N17: =IF(M17>=85%,"Outstanding",IF(M17>=80%,"Excellent",IF(M17>=70%,"Very Good",IF(M17>=60%,"Good",IF(M17>=50%,"Satisfactory",IF(M17>=40%,"Fair","Needs Attention")))))) -> Needs Attention
A18: 13 | K18: 500 | L18: =SUM(D18:J18) -> 0 | M18: =L18/K17 -> 0 | N18: =IF(M18>=85%,"Outstanding",IF(M18>=80%,"Excellent",IF(M18>=70%,"Very Good",IF(M18>=60%,"Good",IF(M18>=50%,"Satisfactory",IF(M18>=40%,"Fair","Needs Attention")))))) -> Needs Attention
A20: ________________________ Principal | K20: ____________________ Class Teacher
B22: Subjects | C22: English | D22: Urdu | E22: GK | F22: Maths | G22: Comp | H22: Islamiat | I22: Sindhi | K22: Summary Grade I
B23: Pass (>=40%) | C23: 0 | D23: 0 | E23: 0 | F23: 0 | G23: 0 | H23: 0 | I23: 0 | K23: No. of Students | L23: 0
B24: Pass% | C24: 0 | D24: 0 | E24: 0 | F24: 0 | G24: 0 | H24: 0 | I24: 0 | K24: Appeared | L24: 0
B25: Fail | C25: 0 | D25: 0 | E25: 0 | F25: 0 | G25: 0 | H25: 0 | I25: 0 | K25: Pass | L25: 0
B26: Fail % | C26: 0 | D26: 0 | E26: 0 | F26: 0 | G26: 0 | H26: 0 | I26: 0 | K26: % Pass | L26: 0
K27: Unsuccessful | L27: 0
K28: % Unsuccessful | L28: 0

Sheet Class  II
A1: Alkhidmat School, Mannan & Qazi Campus, Hala
A2: Mid Term Examination 2025-26
A3: General Information - Grade - II | D3: Consolidated Result Sheet | K3: Aggregate
A4: Sr # | B4: Aghosh ID | C4: Name of Student | D4: Eng | E4: Urdu | F4: GK | G4: Maths | H4: Comp | I4: Islam | J4: Sindhi | K4: Total | L4: Secured Marks | M4: % | N4: Remarks
D5: 100 | E5: 100 | F5: 100 | G5: 100 | H5: Grades | I5: 50 | J5: 50 | K5: =SUM(D5:J5) -> 500
A6: 1 | B6: AAH- 170 | C6: Ali Raza | D6: 88 | E6: 94 | F6: 88 | G6: 84 | H6: B | I6: 43 | J6: 39 | K6: 500 | L6: =SUM(D6:J6) -> 436 | M6: =L6/K5 -> 0.872 | N6: =IF(M6>=85%,"Outstanding",IF(M6>=80%,"Excellent",IF(M6>=70%,"Very Good",IF(M6>=60%,"Good",IF(M6>=50%,"Satisfactory",IF(M6>=40%,"Fair","Needs Attention")))))) -> Outstanding
A7: 2 | B7: AAH- 172 | C7: Abdul Ahad | D7: 90 | E7: 85 | F7: 85 | G7: 93 | H7: B | I7: 40 | J7: 41 | K7: 500 | L7: =SUM(D7:J7) -> 434 | M7: =L7/K6 -> 0.868 | N7: =IF(M7>=85%,"Outstanding",IF(M7>=80%,"Excellent",IF(M7>=70%,"Very Good",IF(M7>=60%,"Good",IF(M7>=50%,"Satisfactory",IF(M7>=40%,"Fair","Needs Attention")))))) -> Outstanding
A8: 3 | B8: AAH-174 | C8: Abdul Sattar | D8: 92.5 | E8: 84.5 | F8: 92 | G8: 81 | H8: A | I8: 47 | J8: 45.5 | K8: 500 | L8: =SUM(D8:J8) -> 442.5 | M8: =L8/K7 -> 0.885 | N8: =IF(M8>=85%,"Outstanding",IF(M8>=80%,"Excellent",IF(M8>=70%,"Very Good",IF(M8>=60%,"Good",IF(M8>=50%,"Satisfactory",IF(M8>=40%,"Fair","Needs Attention")))))) -> Outstanding
A9: 4 | B9: AAH-175 | C9: Faheem Ghani | D9: 54.5 | E9: 64.5 | F9: 48 | G9: 56 | H9: A | I9: 39.5 | J9: 23 | K9: 500 | L9: =SUM(D9:J9) -> 285.5 | M9: =L9/K8 -> 0.571 | N9: =IF(M9>=85%,"Outstanding",IF(M9>=80%,"Excellent",IF(M9>=70%,"Very Good",IF(M9>=60%,"Good",IF(M9>=50%,"Satisfactory",IF(M9>=40%,"Fair","Needs Attention")))))) -> Satisfactory
A10: 5 | B10: AAH- 177 | C10: Ali Shan | D10: 54 | E10: 32 | F10: 66 | G10: 43 | H10: B | I10: 13 | J10: 34.5 | K10: 500 | L10: =SUM(D10:J10) -> 242.5 | M10: =L10/K9 -> 0.485 | N10: =IF(M10>=85%,"Outstanding",IF(M10>=80%,"Excellent",IF(M10>=70%,"Very Good",IF(M10>=60%,"Good",IF(M10>=50%,"Satisfactory",IF(M10>=40%,"Fair","Needs Attention")))))) -> Fair
A11: 6 | B11: AAH- 179 | C11: Muhammad Noraiz | D11: 90 | E11: 97 | F11: 97 | G11: 97 | H11: B | I11: 43.5 | J11: 39.5 | K11: 500 | L11: =SUM(D11:J11) -> 464 | M11: =L11/K10 -> 0.928 | N11: =IF(M11>=85%,"Outstanding",IF(M11>=80%,"Excellent",IF(M11>=70%,"Very Good",IF(M11>=60%,"Good",IF(M11>=50%,"Satisfactory",IF(M11>=40%,"Fair","Needs Attention")))))) -> Outstanding
A12: 7 | B12: AAH- 183 | C12: Syed Hussain Ali | D12: 73 | E12: 67 | F12: 78 | G12: 82 | H12: 78 | I12: 28 | J12: 34 | K12: 500 | L12: =SUM(D12:J12) -> 440 | M12: =L12/K11 -> 0.88 | N12: =IF(M12>=85%,"Outstanding",IF(M12>=80%,"Excellent",IF(M12>=70%,"Very Good",IF(M12>=60%,"Good",IF(M12>=50%,"Satisfactory",IF(M12>=40%,"Fair","Needs Attention")))))) -> Outstanding
A13: 8 | B13: AAH- 184 | C13: Muhammad Mubashir | D13: 73 | E13: 52 | F13: 60 | G13: 69 | H13: B | I13: 39 | J13: 33 | K13: 500 | L13: =SUM(D13:J13) -> 326 | M13: =L13/K12 -> 0.652 | N13: =IF(M13>=85%,"Outstanding",IF(M13>=80%,"Excellent",IF(M13>=70%,"Very Good",IF(M13>=60%,"Good",IF(M13>=50%,"Satisfactory",IF(M13>=40%,"Fair","Needs Attention")))))) -> Good
A14: 9 | B14: AAH- 185 | C14: Ghulam Hyder | D14: 79 | E14: 83.5 | F14: 92 | G14: 58 | H14: C | I14: 32 | J14: 46.5 | K14: 500 | L14: =SUM(D14:J14) -> 391 | M14: =L14/K13 -> 0.782 | N14: =IF(M14>=85%,"Outstanding",IF(M14>=80%,"Excellent",IF(M14>=70%,"Very Good",IF(M14>=60%,"Good",IF(M14>=50%,"Satisfactory",IF(M14>=40%,"Fair","Needs Attention")))))) -> Very Good
A15: 10 | B15: AAH- 186 | C15: Taimoor Ali | D15: 16 | E15: 18.5 | F15: 61 | G15: 36 | H15: C | I15: 4 | J15: 31 | K15: 500 | L15: =SUM(D15:J15) -> 166.5 | M15: =L15/K14 -> 0.333 | N15: =IF(M15>=85%,"Outstanding",IF(M15>=80%,"Excellent",IF(M15>=70%,"Very Good",IF(M15>=60%,"Good",IF(M15>=50%,"Satisfactory",IF(M15>=40%,"Fair","Needs Attention")))))) -> Needs Attention
A16: 11 | B16: AAH- 189 | C16: Ghulam Mustafa | D16: 67 | E16: 43 | F16: 82 | G16: 56.5 | H16: A | I16: 16.5 | J16: 49.5 | K16: 500 | L16: =SUM(D16:J16) -> 314.5 | M16: =L16/K15 -> 0.629 | N16: =IF(M16>=85%,"Outstanding",IF(M16>=80%,"Excellent",IF(M16>=70%,"Very Good",IF(M16>=60%,"Good",IF(M16>=50%,"Satisfactory",IF(M16>=40%,"Fair","Needs Attention")))))) -> Good
A17: 12 | B17: AAH- 194 | C17: Hyder Ali | D17: 98 | E17: 93 | F17: 89 | G17: 99 | H17: A | I17: 40 | J17: 38 | K17: 500 | L17: =SUM(D17:J17) -> 457 | M17: =L17/K16 -> 0.914 | N17: =IF(M17>=85%,"Outstanding",IF(M17>=80%,"Excellent",IF(M17>=70%,"Very Good",IF(M17>=60%,"Good",IF(M17>=50%,"Satisfactory",IF(M17>=40%,"Fair","Needs Attention")))))) -> Outstanding
A18: 13 | B18: AAH- 195 | C18: Ghulam Abbas | D18: 79 | E18: 91 | F18: 75 | G18: 92 | H18: B | I18: 34 | J18: 32 | K18: 500 | L18: =SUM(D18:J18) -> 403 | M18: =L18/K17 -> 0.806 | N18: =IF(M18>=85%,"Outstanding",IF(M18>=80%,"Excellent",IF(M18>=70%,"Very Good",IF(M18>=60%,"Good",IF(M18>=50%,"Satisfactory",IF(M18>=40%,"Fair","Needs Attention")))))) -> Excellent
A19: 14 | B19: AAH- 198 | C19: Zakir Ali | D19: 83.5 | E19: 91 | F19: 95 | G19: 87 | H19: A | I19: 46.5 | J19: 49 | K19: 500 | L19: =SUM(D19:J19) -> 452 | M19: =L19/K18 -> 0.904 | N19: =IF(M19>=85%,"Outstanding",IF(M19>=80%,"Excellent",IF(M19>=70%,"Very Good",IF(M19>=60%,"Good",IF(M19>=50%,"Satisfactory",IF(M19>=40%,"Fair","Needs Attention")))))) -> Outstanding
A20: 15 | B20: AAH- 200 | C20: Shahbaz Ali | D20: 65 | E20: 81 | F20: 60 | G20: 84 | H20: 60 | I20: 20 | J20: 22 | K20: 500 | L20: =SUM(D20:J20) -> 392 | M20: =L20/K19 -> 0.784 | N20: =IF(M20>=85%,"Outstanding",IF(M20>=80%,"Excellent",IF(M20>=70%,"Very Good",IF(M20>=60%,"Good",IF(M20>=50%,"Satisfactory",IF(M20>=40%,"Fair","Needs Attention")))))) -> Very Good
A21: 16 | B21: AAH- 201 | C21: Abdul Raheel | D21: 96 | E21: 92 | F21: 85 | G21: 96 | H21: B | I21: 40 | J21: 38 | K21: 500 | L21: =SUM(D21:J21) -> 447 | M21: =L21/K20 -> 0.894 | N21: =IF(M21>=85%,"Outstanding",IF(M21>=80%,"Excellent",IF(M21>=70%,"Very Good",IF(M21>=60%,"Good",IF(M21>=50%,"Satisfactory",IF(M21>=40%,"Fair","Needs Attention")))))) -> Outstanding
A22: 17 | B22: AAH- 204 | C22: Sikander | D22: 97 | E22: 92 | F22: 63 | G22: 89 | H22: B | I22: 42 | J22: 40 | K22: 500 | L22: =SUM(D22:J22) -> 423 | M22: =L22/K21 -> 0.846 | N22: =IF(M22>=85%,"Outstanding",IF(M22>=80%,"Excellent",IF(M22>=70%,"Very Good",IF(M22>=60%,"Good",IF(M22>=50%,"Satisfactory",IF(M22>=40%,"Fair","Needs Attention")))))) -> Excellent
A23: 18 | B23: AAH- 205 | C23: Abdul Ghani | D23: 57 | E23: 80 | F23: 65 | G23: 86 | H23: B | I23: 20 | J23: 20 | K23: 500 | L23: =SUM(D23:J23) -> 328 | M23: =L23/K22 -> 0.656 | N23: =IF(M23>=85%,"Outstanding",IF(M23>=80%,"Excellent",IF(M23>=70%,"Very Good",IF(M23>=60%,"Good",IF(M23>=50%,"Satisfactory",IF(M23>=40%,"Fair","Needs Attention")))))) -> Good
A24: 19 | B24: AAH- 206 | C24: Amanullah | D24: 77 | E24: 79 | F24: 69 | G24: 88 | H24: B | I24: 22 | J24: 23 | K24: 500 | L24: =SUM(D24:J24) -> 358 | M24: =L24/K23 -> 0.716 | N24: =IF(M24>=85%,"Outstanding",IF(M24>=80%,"Excellent",IF(M24>=70%,"Very Good",IF(M24>=60%,"Good",IF(M24>=50%,"Satisfactory",IF(M24>=40%,"Fair","Needs Attention")))))) -> Very Good
A25: 20 | B25: AAH- 207 | C25: Iqrar Hussain | D25: 88 | E25: 89 | F25: 65 | G25: 88 | H25: B | I25: 30 | J25: 31 | K25: 500 | L25: =SUM(D25:J25) -> 391 | M25: =L25/K24 -> 0.782 | N25: =IF(M25>=85%,"Outstanding",IF(M25>=80%,"Excellent",IF(M25>=70%,"Very Good",IF(M25>=60%,"Good",IF(M25>=50%,"Satisfactory",IF(M25>=40%,"Fair","Needs Attention")))))) -> Very Good
A26: 21 | B26: AAH- | C26: Muhammad Umar | D26: 88 | E26: 87 | F26: 75 | G26: 91 | H26: B | I26: 24 | J26: 20 | K26: 500 | L26: =SUM(D26:J26) -> 385 | M26: =L26/K25 -> 0.77 | N26: =IF(M26>=85%,"Outstanding",IF(M26>=80%,"Excellent",IF(M26>=70%,"Very Good",IF(M26>=60%,"Good",IF(M26>=50%,"Satisfactory",IF(M26>=40%,"Fair","Needs Attention")))))) -> Very Good
A27: ________________________ Principal | K27: _________________ Class Teacher
B29: Subjects | C29: English | D29: Urdu | E29: GK | F29: Maths | G29: Comp | H29: Islamiat | I29: Sindhi | L29: Summary Grade II
B30: Pass (>=40%) | C30: =21-C32 -> 20 | D30: =21-D32 -> 19 | E30: =21-E32 -> 21 | F30: =21-F32 -> 20 | G30: =21-G32 -> 21 | H30: =21-H32 -> 18 | I30: =21-I32 -> 21 | L30: No. of Students | M30: 21
B31: Pass% | C31: =C30/21 -> 0.95238095 | D31: =D30/21 -> 0.9047619 | E31: =E30/21 -> 1 | F31: =F30/21 -> 0.95238095 | G31: =G30/21 -> 1 | H31: =H30/21 -> 0.85714286 | I31: =I30/21 -> 1 | L31: Appeared | M31: 21
B32: Fail | C32: 1 | D32: 2 | E32: 0 | F32: 1 | G32: 0 | H32: 3 | I32: 0 | L32: Pass | M32: 20
B33: Fail % | C33: =100%-C31 -> 0.047619048 | D33: =100%-D31 -> 0.095238095 | E33: =100%-E31 -> 0 | F33: =100%-F31 -> 0.047619048 | G33: =100%-G31 -> 0 | H33: =100%-H31 -> 0.14285714 | I33: =100%-I31 -> 0 | L33: % Pass | M33: =M32/M31 -> 0.95238095
L34: Unsuccessful | M34: =M31-M32 -> 1
L35: % Unsuccessful | M35: =M34/M31 -> 0.047619048

Sheet Class III
A1: Alkhidmat School, Mannan & Qazi Campus, Hala
A2: Mid Term Examination 2025-26
A3: General Information - Grade III | D3: Consolidated Result Sheet | K3: Aggregate
A4: Sr # | B4: Aghosh ID | C4: Name of Student | D4: Eng | E4: Urdu | F4: GK | G4: Maths | H4: Comp | I4: Islam | J4: Sindhi | K4: Total | L4: Secured Marks | M4: % | N4: Remarks
D5: 100 | E5: 100 | F5: 100 | G5: 100 | H5: Grades | I5: 50 | J5: 50 | K5: =SUM(D5:J5) -> 500
A6: 1 | B6: AAH-99 | C6: Muzammil | D6: 71 | E6: 86 | F6: 82 | G6: 85 | H6: A | I6: 42.5 | J6: 45 | K6: 500 | L6: =SUM(D6:J6) -> 411.5 | M6: =L6/K6 -> 0.823 | N6: =IF(M6>=85%,"Outstanding",IF(M6>=80%,"Excellent",IF(M6>=70%,"Very Good",IF(M6>=60%,"Good",IF(M6>=50%,"Satisfactory",IF(M6>=40%,"Fair","Needs Attention")))))) -> Excellent
A7: 2 | B7: AAH-103 | C7: Sikandar Ali | D7: 89.5 | E7: 61 | F7: 68 | G7: 95 | H7: B | I7: 39 | J7: 50 | K7: 500 | L7: =SUM(D7:J7) -> 402.5 | M7: =L7/K7 -> 0.805 | N7: =IF(M7>=85%,"Outstanding",IF(M7>=80%,"Excellent",IF(M7>=70%,"Very Good",IF(M7>=60%,"Good",IF(M7>=50%,"Satisfactory",IF(M7>=40%,"Fair","Needs Attention")))))) -> Excellent
A8: 3 | B8: AAH-106 | C8: Mudasir | D8: 84 | E8: 64 | F8: 88 | G8: 96 | H8: B | I8: 50 | J8: 49.5 | K8: 500 | L8: =SUM(D8:J8) -> 431.5 | M8: =L8/K8 -> 0.863 | N8: =IF(M8>=85%,"Outstanding",IF(M8>=80%,"Excellent",IF(M8>=70%,"Very Good",IF(M8>=60%,"Good",IF(M8>=50%,"Satisfactory",IF(M8>=40%,"Fair","Needs Attention")))))) -> Outstanding
A9: 4 | B9: AAH- 110 | C9: Muhammad Jaan | D9: 46.5 | E9: 40.5 | F9: 44 | G9: 82 | H9: B | I9: 12 | J9: 30 | K9: 500 | L9: =SUM(D9:J9) -> 255 | M9: =L9/K9 -> 0.51 | N9: =IF(M9>=85%,"Outstanding",IF(M9>=80%,"Excellent",IF(M9>=70%,"Very Good",IF(M9>=60%,"Good",IF(M9>=50%,"Satisfactory",IF(M9>=40%,"Fair","Needs Attention")))))) -> Satisfactory
A10: 5 | B10: AAH-112 | C10: Mansoor Ali | D10: 23.5 | E10: 14.5 | F10: 21 | G10: 54 | H10: A | I10: 12 | J10: 22.5 | K10: 500 | L10: =SUM(D10:J10) -> 147.5 | M10: =L10/K10 -> 0.295 | N10: =IF(M10>=85%,"Outstanding",IF(M10>=80%,"Excellent",IF(M10>=70%,"Very Good",IF(M10>=60%,"Good",IF(M10>=50%,"Satisfactory",IF(M10>=40%,"Fair","Needs Attention")))))) -> Needs Attention
A11: 6 | B11: AAH-115 | C11: Hamad Ullah | D11: 86.5 | E11: 97.5 | F11: 87.5 | G11: 88.5 | H11: A | I11: 45 | J11: 49 | K11: 500 | L11: =SUM(D11:J11) -> 454 | M11: =L11/K11 -> 0.908 | N11: =IF(M11>=85%,"Outstanding",IF(M11>=80%,"Excellent",IF(M11>=70%,"Very Good",IF(M11>=60%,"Good",IF(M11>=50%,"Satisfactory",IF(M11>=40%,"Fair","Needs Attention")))))) -> Outstanding
A12: 7 | B12: AAH-117 | C12: Mubashir Ahmed | D12: 42 | E12: 57.5 | F12: 52 | G12: 41.5 | H12: B | I12: 24 | J12: 27 | K12: 500 | L12: =SUM(D12:J12) -> 244 | M12: =L12/K12 -> 0.488 | N12: =IF(M12>=85%,"Outstanding",IF(M12>=80%,"Excellent",IF(M12>=70%,"Very Good",IF(M12>=60%,"Good",IF(M12>=50%,"Satisfactory",IF(M12>=40%,"Fair","Needs Attention")))))) -> Fair
A13: 8 | B13: AAH-122 | C13: Faraz Ahmad | D13: 92.5 | E13: 93 | F13: 96 | G13: 96 | H13: A | I13: 50 | J13: 50 | K13: 500 | L13: =SUM(D13:J13) -> 477.5 | M13: =L13/K13 -> 0.955 | N13: =IF(M13>=85%,"Outstanding",IF(M13>=80%,"Excellent",IF(M13>=70%,"Very Good",IF(M13>=60%,"Good",IF(M13>=50%,"Satisfactory",IF(M13>=40%,"Fair","Needs Attention")))))) -> Outstanding
A14: 9 | B14: AAH-123 | C14: Abdul Samad | D14: 62.5 | E14: 93.5 | F14: 86 | G14: 69 | H14: A | I14: 44.5 | J14: 39 | K14: 500 | L14: =SUM(D14:J14) -> 394.5 | M14: =L14/K14 -> 0.789 | N14: =IF(M14>=85%,"Outstanding",IF(M14>=80%,"Excellent",IF(M14>=70%,"Very Good",IF(M14>=60%,"Good",IF(M14>=50%,"Satisfactory",IF(M14>=40%,"Fair","Needs Attention")))))) -> Very Good
A15: 10 | B15: AAH-129 | C15: Tariq Shahzad | D15: 76.5 | E15: 90.5 | F15: 92 | G15: 85.5 | H15: A | I15: 49 | J15: 40 | K15: 500 | L15: =SUM(D15:J15) -> 433.5 | M15: =L15/K15 -> 0.867 | N15: =IF(M15>=85%,"Outstanding",IF(M15>=80%,"Excellent",IF(M15>=70%,"Very Good",IF(M15>=60%,"Good",IF(M15>=50%,"Satisfactory",IF(M15>=40%,"Fair","Needs Attention")))))) -> Outstanding
A16: 11 | B16: AAH-130 | C16: Muhammad Ibrahim | D16: 42 | E16: 44.5 | F16: 64 | G16: 79 | H16: B | I16: 25 | J16: 39.5 | K16: 500 | L16: =SUM(D16:J16) -> 294 | M16: =L16/K16 -> 0.588 | N16: =IF(M16>=85%,"Outstanding",IF(M16>=80%,"Excellent",IF(M16>=70%,"Very Good",IF(M16>=60%,"Good",IF(M16>=50%,"Satisfactory",IF(M16>=40%,"Fair","Needs Attention")))))) -> Satisfactory
A17: 12 | B17: AAH-131 | C17: Tariq Khan | D17: 43 | E17: 65.5 | F17: 48 | G17: 70.5 | H17: B | I17: 22 | J17: 31 | K17: 500 | L17: =SUM(D17:J17) -> 280 | M17: =L17/K17 -> 0.56 | N17: =IF(M17>=85%,"Outstanding",IF(M17>=80%,"Excellent",IF(M17>=70%,"Very Good",IF(M17>=60%,"Good",IF(M17>=50%,"Satisfactory",IF(M17>=40%,"Fair","Needs Attention")))))) -> Satisfactory
... A37: 32 | B37: AAH- | C37: Ayan Ali | D37: 43.5 | E37: 41.5 | F37: 45.5 | G37: 42 | H37: C | I37: 28.5 | J37: 26 | K37: 500 | L37: =SUM(D37:J37) -> 227 | M37: =L37/K37 -> 0.454 | N37: =IF(M37>=85%,"Outstanding",IF(M37>=80%,"Excellent",IF(M37>=70%,"Very Good",IF(M37>=60%,"Good",IF(M37>=50%,"Satisfactory",IF(M37>=40%,"Fair","Needs Attention")))))) -> Fair
A38: ________________________ Principal | K38: __________________ Class Teacher
L40: Summary Grade III
B41: Subjects | C41: English | D41: Urdu | E41: GK | F41: Maths | G41: Comp | H41: Islamiat | I41: Sindhi | L41: No. of Students | M41: 32
B42: Pass (>=40%) | C42: =32-C44 -> 29 | D42: =32-D44 -> 29 | E42: =32-E44 -> 30 | F42: =32-F44 -> 32 | G42: =32-G44 -> 32 | H42: =32-H44 -> 28 | I42: =32-I44 -> 31 | L42: Appeared | M42: 32
B43: Pass% | C43: =C42/32 -> 0.90625 | D43: =D42/32 -> 0.90625 | E43: =E42/32 -> 0.9375 | F43: =F42/32 -> 1 | G43: =G42/32 -> 1 | H43: =H42/32 -> 0.875 | I43: =I42/32 -> 0.96875 | L43: Pass | M43: 30
B44: Fail | C44: 3 | D44: 3 | E44: 2 | F44: 0 | G44: 0 | H44: 4 | I44: 1 | L44: % Pass | M44: =M43/M42 -> 0.9375
B45: Fail % | C45: =100%-C43 -> 0.09375 | D45: =100%-D43 -> 0.09375 | E45: =100%-E43 -> 0.0625 | F45: =100%-F43 -> 0 | G45: =100%-G43 -> 0 | H45: =100%-H43 -> 0.125 | I45: =100%-I43 -> 0.03125 | L45: Unsuccessful | M45: =M42-M43 -> 2
L46: % Unsuccessful | M46: =M45/M42 -> 0.0625

Sheet Class IV
A1: Alkhidmat School, Mannan & Qazi Campus, Hala
A2: Mid Term Examination 2025-26
A3: General Information - Grade IV | D3: Consolidated Result Sheet | L3: Aggregate
A4: Sr # | B4: Aghosh ID | C4: Name of Student | D4: Eng | E4: Urdu | F4: Science | G4: Maths | H4: Comp | I4: S.S | J4: Islam | K4: Sindhi | L4: Total | M4: Secured Marks | N4: % | O4: Remarks
D5: 100 | E5: 100 | F5: 100 | G5: 100 | H5: Grades | I5: 50 | J5: 50 | K5: 50 | L5: =SUM(D5:K5) -> 550
A6: 1 | B6: AAH-075 | C6: Arman | D6: 4 | E6: 52 | F6: 27.5 | G6: 23 | H6: C | I6: 20 | J6: 22 | K6: 12 | L6: 550 | M6: =SUM(D6:K6) -> 160.5 | N6: =M6/L5 -> 0.29181818 | O6: =IF(N6>=85%,"Outstanding",IF(N6>=80%,"Excellent",IF(N6>=70%,"Very Good",IF(N6>=60%,"Good",IF(N6>=50%,"Satisfactory",IF(N6>=40%,"Fair","Needs Attention")))))) -> Needs Attention
A7: 2 | B7: AAH-077 | C7: Muhammad Uzair | D7: 43 | E7: 45 | F7: 54.5 | G7: 48 | H7: B | I7: 28 | J7: 20 | K7: 25 | L7: 550 | M7: =SUM(D7:K7) -> 263.5 | N7: =M7/L6 -> 0.47909091 | O7: =IF(N7>=85%,"Outstanding",IF(N7>=80%,"Excellent",IF(N7>=70%,"Very Good",IF(N7>=60%,"Good",IF(N7>=50%,"Satisfactory",IF(N7>=40%,"Fair","Needs Attention")))))) -> Fair
A8: 3 | B8: AAH-081 | C8: Rehman Ali | D8: 78 | E8: 84.5 | F8: 79 | G8: 87.5 | H8: A | I8: 38 | J8: 41 | K8: 47 | L8: 550 | M8: =SUM(D8:K8) -> 455 | N8: =M8/L7 -> 0.82727273 | O8: =IF(N8>=85%,"Outstanding",IF(N8>=80%,"Excellent",IF(N8>=70%,"Very Good",IF(N8>=60%,"Good",IF(N8>=50%,"Satisfactory",IF(N8>=40%,"Fair","Needs Attention")))))) -> Excellent
A9: 4 | B9: AAH-119 | C9: Ali Bux | D9: 73.5 | E9: 98 | F9: 84.5 | G9: 96 | H9: A | I9: 48 | J9: 47.5 | K9: 49 | L9: 550 | M9: =SUM(D9:K9) -> 496.5 | N9: =M9/L8 -> 0.90272727 | O9: =IF(N9>=85%,"Outstanding",IF(N9>=80%,"Excellent",IF(N9>=70%,"Very Good",IF(N9>=60%,"Good",IF(N9>=50%,"Satisfactory",IF(N9>=40%,"Fair","Needs Attention")))))) -> Outstanding
A10: 5 | B10: AAH-120 | C10: Sumair Ali | D10: 40 | E10: 54.5 | F10: 44.5 | G10: 75 | H10: B | I10: 24 | J10: 20 | K10: 40 | L10: 550 | M10: =SUM(D10:K10) -> 298 | N10: =M10/L9 -> 0.54181818 | O10: =IF(N10>=85%,"Outstanding",IF(N10>=80%,"Excellent",IF(N10>=70%,"Very Good",IF(N10>=60%,"Good",IF(N10>=50%,"Satisfactory",IF(N10>=40%,"Fair","Needs Attention")))))) -> Satisfactory
A11: 6 | B11: AAH-134 | C11: Abdul Samad | D11: 41 | E11: 67 | F11: 64.5 | G11: 58.5 | H11: B | I11: 30 | J11: 39.5 | K11: 44 | L11: 550 | M11: =SUM(D11:K11) -> 344.5 | N11: =M11/L10 -> 0.62636364 | O11: =IF(N11>=85%,"Outstanding",IF(N11>=80%,"Excellent",IF(N11>=70%,"Very Good",IF(N11>=60%,"Good",IF(N11>=50%,"Satisfactory",IF(N11>=40%,"Fair","Needs Attention")))))) -> Good
A12: 7 | B12: AAH-166 | C12: Abdul Mannan | D12: 75 | E12: 85.5 | F12: 78 | G12: 93.5 | H12: A | I12: 40 | J12: 41.5 | K12: 38 | L12: 550 | M12: =SUM(D12:K12) -> 451.5 | N12: =M12/L11 -> 0.82090909 | O12: =IF(N12>=85%,"Outstanding",IF(N12>=80%,"Excellent",IF(N12>=70%,"Very Good",IF(N12>=60%,"Good",IF(N12>=50%,"Satisfactory",IF(N12>=40%,"Fair","Needs Attention")))))) -> Excellent
A13: 8 | B13: AAH-168 | C13: Gul Jan | D13: 87.5 | E13: 95.5 | F13: 88 | G13: 97 | H13: A | I13: 47 | J13: 48 | K13: 48 | L13: 550 | M13: =SUM(D13:K13) -> 511 | N13: =M13/L12 -> 0.92909091 | O13: =IF(N13>=85%,"Outstanding",IF(N13>=80%,"Excellent",IF(N13>=70%,"Very Good",IF(N13>=60%,"Good",IF(N13>=50%,"Satisfactory",IF(N13>=40%,"Fair","Needs Attention")))))) -> Outstanding
A14: 9 | B14: AAH-173 | C14: Muhammad Shayan | D14: 43 | E14: 62 | F14: 57 | G14: 42 | H14: A | I14: 34.5 | J14: 32 | K14: 41.5 | L14: 550 | M14: =SUM(D14:K14) -> 312 | N14: =M14/L13 -> 0.56727273 | O14: =IF(N14>=85%,"Outstanding",IF(N14>=80%,"Excellent",IF(N14>=70%,"Very Good",IF(N14>=60%,"Good",IF(N14>=50%,"Satisfactory",IF(N14>=40%,"Fair","Needs Attention")))))) -> Satisfactory
A15: 10 | B15: AAH-182 | C15: Syed Hassan Ali | D15: 93 | E15: 98 | F15: 99 | G15: 100 | H15: A | I15: 48 | J15: 44 | K15: 46.5 | L15: 550 | M15: =SUM(D15:K15) -> 528.5 | N15: =M15/L14 -> 0.96090909 | O15: =IF(N15>=85%,"Outstanding",IF(N15>=80%,"Excellent",IF(N15>=70%,"Very Good",IF(N15>=60%,"Good",IF(N15>=50%,"Satisfactory",IF(N15>=40%,"Fair","Needs Attention")))))) -> Outstanding
A16: 11 | B16: AAH-193 | C16: Mudasir | D16: 86 | E16: 52 | F16: 87 | G16: 95 | H16: B | I16: 45 | J16: 45 | K16: 33.5 | L16: 550 | M16: =SUM(D16:K16) -> 443.5 | N16: =M16/L15 -> 0.80636364 | O16: =IF(N16>=85%,"Outstanding",IF(N16>=80%,"Excellent",IF(N16>=70%,"Very Good",IF(N16>=60%,"Good",IF(N16>=50%,"Satisfactory",IF(N16>=40%,"Fair","Needs Attention")))))) -> Excellent
A18: ________________________ Principal | K18: _________________ Class Teacher
M20: V
C21: Subjects | D21: English | E21: Urdu | F21: Science | G21: Maths | H21: Comp | I21: SS | J21: Islamiat | K21: Sindhi | M21: No. of Students | N21: 11
C22: Pass (>=40%) | D22: =11-D24 -> 10 | E22: =11-E24 -> 11 | F22: =11-F24 -> 10 | G22: =11-G24 -> 10 | H22: =11-H24 -> 11 | I22: =11-I24 -> 11 | J22: =11-J24 -> 10 | K22: =11-K24 -> 10 | M22: Appeared | N22: 11
C23: Pass% | D23: =D22/11 -> 0.90909091 | E23: =E22/11 -> 1 | F23: =F22/11 -> 0.90909091 | G23: =G22/11 -> 0.90909091 | H23: =H22/11 -> 1 | I23: =I22/11 -> 1 | J23: =J22/11 -> 0.90909091 | K23: =K22/11 -> 0.90909091 | M23: Pass | N23: 10
C24: Fail | D24: 1 | E24: 0 | F24: 1 | G24: 1 | H24: 0 | I24: 0 | J24: 1 | K24: 1 | M24: % Pass | N24: =N23/N22 -> 0.90909091
C25: Fail % | D25: =100%-D23 -> 0.090909091 | E25: =100%-E23 -> 0 | F25: =100%-F23 -> 0.090909091 | G25: =100%-G23 -> 0.090909091 | H25: =100%-H23 -> 0 | I25: =100%-I23 -> 0 | J25: =100%-J23 -> 0.090909091 | K25: =100%-K23 -> 0.090909091 | M25: Unsuccessful | N25: =N22-N23 -> 1
M26: % Unsuccessful | N26: =N25/N22 -> 0.090909091

Sheet Class V
A1: Alkhidmat School, Mannan & Qazi Campus, Hala
A2: Mid Term Examination 2025-26
A3: General Information - Grade V | D3: Consolidated Result Sheet | L3: Aggregate
A4: Sr # | B4: Aghosh ID | C4: Name of Student | D4: Eng | E4: Urdu | F4: Science | G4: Maths | H4: Comp | I4: S.S | J4: Islam | K4: Sindhi | L4: Total | M4: Secured Marks | N4: % | O4: Remarks
D5: 100 | E5: 100 | F5: 100 | G5: 100 | H5: Grades | I5: 50 | J5: 50 | K5: 50 | L5: =SUM(D5:K5) -> 550
A6: 1 | B6: AAH-076 | C6: Muhammad Asim | D6: 8 | E6: 24 | F6: 18 | G6: 2 | H6: B | I6: 15.5 | J6: 14 | K6: 7 | L6: 550 | M6: =SUM(D6:K6) -> 88.5 | N6: =M6/L5 -> 0.16090909 | O6: =IF(N6>=85%,"Outstanding",IF(N6>=80%,"Excellent",IF(N6>=70%,"Very Good",IF(N6>=60%,"Good",IF(N6>=50%,"Satisfactory",IF(N6>=40%,"Fair","Needs Attention")))))) -> Needs Attention
A7: 2 | B7: AAH-078 | C7: Hasnain Ali | D7: 16 | E7: 34.5 | F7: 35 | G7: 22 | H7: C | I7: 21.5 | J7: 24 | K7: 9 | L7: 550 | M7: =SUM(D7:K7) -> 162 | N7: =M7/L6 -> 0.29454545 | O7: =IF(N7>=85%,"Outstanding",IF(N7>=80%,"Excellent",IF(N7>=70%,"Very Good",IF(N7>=60%,"Good",IF(N7>=50%,"Satisfactory",IF(N7>=40%,"Fair","Needs Attention")))))) -> Needs Attention
A8: 3 | B8: AAH-079 | C8: Kashan | D8: Absent | E8: Absent | F8: Absent | G8: Absent | H8: Absent | I8: Absent | J8: Absent | K8: Absent | L8: 550 | M8: =SUM(D8:K8) -> 0 | N8: =M8/L7 -> 0 | O8: =IF(N8>=85%,"Outstanding",IF(N8>=80%,"Excellent",IF(N8>=70%,"Very Good",IF(N8>=60%,"Good",IF(N8>=50%,"Satisfactory",IF(N8>=40%,"Fair","Needs Attention")))))) -> Needs Attention
A9: 4 | B9: AAH-83 | C9: Aqib | D9: 56 | E9: 56.5 | F9: 82 | G9: 81 | H9: B | I9: 38 | J9: 27 | K9: 33.5 | L9: 550 | M9: =SUM(D9:K9) -> 374 | N9: =M9/L8 -> 0.68 | O9: =IF(N9>=85%,"Outstanding",IF(N9>=80%,"Excellent",IF(N9>=70%,"Very Good",IF(N9>=60%,"Good",IF(N9>=50%,"Satisfactory",IF(N9>=40%,"Fair","Needs Attention")))))) -> Good
A10: 5 | B10: AAH-085 | C10: Ehsan | D10: 63 | E10: 67 | F10: 75 | G10: 42 | H10: A | I10: 31 | J10: 48.5 | K10: 44 | L10: 550 | M10: =SUM(D10:K10) -> 370.5 | N10: =M10/L9 -> 0.67363636 | O10: =IF(N10>=85%,"Outstanding",IF(N10>=80%,"Excellent",IF(N10>=70%,"Very Good",IF(N10>=60%,"Good",IF(N10>=50%,"Satisfactory",IF(N10>=40%,"Fair","Needs Attention")))))) -> Good
A11: 6 | B11: AAH-090 | C11: Waqas Mashooq | D11: 13 | E11: 59 | F11: 25 | G11: 44.5 | H11: C | I11: 29 | J11: 34 | K11: 28 | L11: 550 | M11: =SUM(D11:K11) -> 232.5 | N11: =M11/L10 -> 0.42272727 | O11: =IF(N11>=85%,"Outstanding",IF(N11>=80%,"Excellent",IF(N11>=70%,"Very Good",IF(N11>=60%,"Good",IF(N11>=50%,"Satisfactory",IF(N11>=40%,"Fair","Needs Attention")))))) -> Fair
A12: 7 | B12: AAH-92 | C12: Qadeer Ali | D12: 37 | E12: 3 | F12: 30 | G12: 63 | H12: B | I12: 20 | J12: 9.5 | K12: 15 | L12: 550 | M12: =SUM(D12:K12) -> 177.5 | N12: =M12/L11 -> 0.32272727 | O12: =IF(N12>=85%,"Outstanding",IF(N12>=80%,"Excellent",IF(N12>=70%,"Very Good",IF(N12>=60%,"Good",IF(N12>=50%,"Satisfactory",IF(N12>=40%,"Fair","Needs Attention")))))) -> Needs Attention
A13: 8 | B13: AAH-94 | C13: Hassnain | D13: 11 | E13: 2 | F13: 30 | G13: 18 | H13: C | I13: 20 | J13: 8 | K13: 20 | L13: 550 | M13: =SUM(D13:K13) -> 109 | N13: =M13/L12 -> 0.19818182 | O13: =IF(N13>=85%,"Outstanding",IF(N13>=80%,"Excellent",IF(N13>=70%,"Very Good",IF(N13>=60%,"Good",IF(N13>=50%,"Satisfactory",IF(N13>=40%,"Fair","Needs Attention")))))) -> Needs Attention
A14: 9 | B14: AAH-096 | C14: Maawiya Mehmood | D14: 53.5 | E14: 83.5 | F14: 54.5 | G14: 31.5 | H14: B | I14: 40.5 | J14: 44.5 | K14: 43 | L14: 550 | M14: =SUM(D14:K14) -> 351 | N14: =M14/L13 -> 0.63818182 | O14: =IF(N14>=85%,"Outstanding",IF(N14>=80%,"Excellent",IF(N14>=70%,"Very Good",IF(N14>=60%,"Good",IF(N14>=50%,"Satisfactory",IF(N14>=40%,"Fair","Needs Attention")))))) -> Good
A15: 10 | B15: AAH-097 | C15: Fayyaz Ahmed | D15: 37 | E15: 62.5 | F15: 45.5 | G15: 29 | H15: C | I15: 25 | J15: 41 | K15: 43.5 | L15: 550 | M15: =SUM(D15:K15) -> 283.5 | N15: =M15/L14 -> 0.51545455 | O15: =IF(N15>=85%,"Outstanding",IF(N15>=80%,"Excellent",IF(N15>=70%,"Very Good",IF(N15>=60%,"Good",IF(N15>=50%,"Satisfactory",IF(N15>=40%,"Fair","Needs Attention")))))) -> Satisfactory
A16: 11 | B16: AAH-100 | C16: Muhammad Irfan | D16: 67 | E16: 88 | F16: 84 | G16: 66 | H16: A | I16: 44 | J16: 40 | K16: 46 | L16: 550 | M16: =SUM(D16:K16) -> 435 | N16: =M16/L15 -> 0.79090909 | O16: =IF(N16>=85%,"Outstanding",IF(N16>=80%,"Excellent",IF(N16>=70%,"Very Good",IF(N16>=60%,"Good",IF(N16>=50%,"Satisfactory",IF(N16>=40%,"Fair","Needs Attention")))))) -> Very Good
A17: 12 | B17: AAH-101 | C17: Muhammad Ahsan | D17: 44 | E17: 40.5 | F17: 19 | G17: 79 | H17: B | I17: 20 | J17: 20 | K17: 34 | L17: 550 | M17: =SUM(D17:K17) -> 256.5 | N17: =M17/L16 -> 0.46636364 | O17: =IF(N17>=85%,"Outstanding",IF(N17>=80%,"Excellent",IF(N17>=70%,"Very Good",IF(N17>=60%,"Good",IF(N17>=50%,"Satisfactory",IF(N17>=40%,"Fair","Needs Attention")))))) -> Fair
A18: 13 | B18: AAH-104 | C18: Abdul Wadood | D18: 57 | E18: 82 | F18: 80.5 | G18: 73.5 | H18: A | I18: 40 | J18: 36 | K18: 35 | L18: 550 | M18: =SUM(D18:K18) -> 404 | N18: =M18/L17 -> 0.73454545 | O18: =IF(N18>=85%,"Outstanding",IF(N18>=80%,"Excellent",IF(N18>=70%,"Very Good",IF(N18>=60%,"Good",IF(N18>=50%,"Satisfactory",IF(N18>=40%,"Fair","Needs Attention")))))) -> Very Good
A19: 14 | B19: AAH-105 | C19: Nadeem | D19: 54.5 | E19: 55 | F19: 44 | G19: 64 | H19: B | I19: 20 | J19: 20 | K19: 43 | L19: 550 | M19: =SUM(D19:K19) -> 300.5 | N19: =M19/L18 -> 0.54636364 | O19: =IF(N19>=85%,"Outstanding",IF(N19>=80%,"Excellent",IF(N19>=70%,"Very Good",IF(N19>=60%,"Good",IF(N19>=50%,"Satisfactory",IF(N19>=40%,"Fair","Needs Attention")))))) -> Satisfactory
A20: 15 | B20: AAH-107 | C20: Rehan | D20: 18 | E20: 23.5 | F20: 40 | G20: 21 | H20: C | I20: 27 | J20: 20 | K20: 11 | L20: 550 | M20: =SUM(D20:K20) -> 160.5 | N20: =M20/L19 -> 0.29181818 | O20: =IF(N20>=85%,"Outstanding",IF(N20>=80%,"Excellent",IF(N20>=70%,"Very Good",IF(N20>=60%,"Good",IF(N20>=50%,"Satisfactory",IF(N20>=40%,"Fair","Needs Attention")))))) -> Needs Attention
... A23: 18 | B23: AAH-125 | C23: Muhammad Sufyan | D23: 23 | E23: 19.5 | F23: 30 | G23: 35 | H23: B | I23: 23.5 | J23: 30.5 | K23: 18.5 | L23: 550 | M23: =SUM(D23:K23) -> 180 | N23: =M23/L22 -> 0.32727273 | O23: =IF(N23>=85%,"Outstanding",IF(N23>=80%,"Excellent",IF(N23>=70%,"Very Good",IF(N23>=60%,"Good",IF(N23>=50%,"Satisfactory",IF(N23>=40%,"Fair","Needs Attention")))))) -> Needs Attention
A24: 19 | B24: AAH-141 | C24: Musab Ahmed | D24: Absent | E24: Absent | F24: Absent | G24: Absent | H24: A | I24: Absent | J24: Absent | K24: Absent | L24: 550 | M24: =SUM(D24:K24) -> 0 | N24: =M24/L23 -> 0 | O24: =IF(N24>=85%,"Outstanding",IF(N24>=80%,"Excellent",IF(N24>=70%,"Very Good",IF(N24>=60%,"Good",IF(N24>=50%,"Satisfactory",IF(N24>=40%,"Fair","Needs Attention")))))) -> Needs Attention
A25: 20 | B25: AAH-142 | C25: Farooque Ahmed | D25: Absent | E25: Absent | F25: Absent | G25: Absent | H25: A | I25: Absent | J25: Absent | K25: Absent | L25: 550 | M25: =SUM(D25:K25) -> 0 | N25: =M25/L24 -> 0 | O25: =IF(N25>=85%,"Outstanding",IF(N25>=80%,"Excellent",IF(N25>=70%,"Very Good",IF(N25>=60%,"Good",IF(N25>=50%,"Satisfactory",IF(N25>=40%,"Fair","Needs Attention")))))) -> Needs Attention
A26: 21 | B26: AAH-149 | C26: Idress | D26: 87 | E26: 95 | F26: 95 | G26: 64 | H26: A | I26: 49 | J26: 50 | K26: 49.5 | L26: 550 | M26: =SUM(D26:K26) -> 489.5 | N26: =M26/L25 -> 0.89 | O26: =IF(N26>=85%,"Outstanding",IF(N26>=80%,"Excellent",IF(N26>=70%,"Very Good",IF(N26>=60%,"Good",IF(N26>=50%,"Satisfactory",IF(N26>=40%,"Fair","Needs Attention")))))) -> Outstanding
A27: 22 | B27: AAH-150 | C27: Safi Ullah | D27: 26 | E27: 32.5 | F27: 40 | G27: 33 | H27: C | I27: 28.5 | J27: 37.5 | K27: 21 | L27: 550 | M27: =SUM(D27:K27) -> 218.5 | N27: =M27/L26 -> 0.39727273 | O27: =IF(N27>=85%,"Outstanding",IF(N27>=80%,"Excellent",IF(N27>=70%,"Very Good",IF(N27>=60%,"Good",IF(N27>=50%,"Satisfactory",IF(N27>=40%,"Fair","Needs Attention")))))) -> Needs Attention
A28: 23 | B28: AAH-164 | C28: Fahad Hussain | D28: 60 | E28: 91 | F28: 83.5 | G28: 54 | H28: A | I28: 44 | J28: 47 | K28: 38.5 | L28: 550 | M28: =SUM(D28:K28) -> 418 | N28: =M28/L27 -> 0.76 | O28: =IF(N28>=85%,"Outstanding",IF(N28>=80%,"Excellent",IF(N28>=70%,"Very Good",IF(N28>=60%,"Good",IF(N28>=50%,"Satisfactory",IF(N28>=40%,"Fair","Needs Attention")))))) -> Very Good
A29: 24 | B29: AAH-167 | C29: Abdul Wajid | D29: 69 | E29: 91.5 | F29: 89 | G29: 80 | H29: A | I29: 48 | J29: 48 | K29: 50 | L29: 550 | M29: =SUM(D29:K29) -> 475.5 | N29: =M29/L28 -> 0.86454545 | O29: =IF(N29>=85%,"Outstanding",IF(N29>=80%,"Excellent",IF(N29>=70%,"Very Good",IF(N29>=60%,"Good",IF(N29>=50%,"Satisfactory",IF(N29>=40%,"Fair","Needs Attention")))))) -> Outstanding
A30: 25 | B30: AAH-180 | C30: Moviz | D30: 24 | E30: 72.5 | F30: 64.5 | G30: 26.5 | H30: C | I30: 30 | J30: 27.5 | K30: 42.5 | L30: 550 | M30: =SUM(D30:K30) -> 287.5 | N30: =M30/L29 -> 0.52272727 | O30: =IF(N30>=85%,"Outstanding",IF(N30>=80%,"Excellent",IF(N30>=70%,"Very Good",IF(N30>=60%,"Good",IF(N30>=50%,"Satisfactory",IF(N30>=40%,"Fair","Needs Attention")))))) -> Satisfactory
A31: 26 | B31: AAH-202 | C31: Saqlain Hader | D31: 25 | E31: 50.5 | F31: 32.5 | G31: 20.5 | H31: B | I31: 28 | J31: 31.5 | K31: 14 | L31: 550 | M31: =SUM(D31:K31) -> 202 | N31: =M31/L30 -> 0.36727273 | O31: =IF(N31>=85%,"Outstanding",IF(N31>=80%,"Excellent",IF(N31>=70%,"Very Good",IF(N31>=60%,"Good",IF(N31>=50%,"Satisfactory",IF(N31>=40%,"Fair","Needs Attention")))))) -> Needs Attention
A33: ________________________ Principal | K33: _________________ Class Teacher
M35: V
C36: Subjects | D36: English | E36: Urdu | F36: Science | G36: Maths | H36: Comp | I36: SS | J36: Islamiat | K36: Sindhi | M36: No. of Students | N36: 26
C37: Pass (>=40%) | D37: =23-D39 -> 13 | E37: =23-E39 -> 18 | F37: =23-F39 -> 17 | G37: =23-G39 -> 13 | H37: =23-H39 -> 23 | I37: =23-I39 -> 22 | J37: =23-J39 -> 22 | K37: =23-K39 -> 17 | M37: Appeared | N37: 23
C38: Pass% | D38: =D37/23 -> 0.56521739 | E38: =E37/23 -> 0.7826087 | F38: =F37/23 -> 0.73913043 | G38: =G37/23 -> 0.56521739 | H38: =H37/23 -> 1 | I38: =I37/23 -> 0.95652174 | J38: =J37/23 -> 0.95652174 | K38: =K37/23 -> 0.73913043 | M38: Pass | N38: 15
C39: Fail | D39: 10 | E39: 5 | F39: 6 | G39: 10 | H39: 0 | I39: 1 | J39: 1 | K39: 6 | M39: % Pass | N39: =N38/N37 -> 0.65217391
C40: Fail % | D40: =100%-D38 -> 0.43478261 | E40: =100%-E38 -> 0.2173913 | F40: =100%-F38 -> 0.26086957 | G40: =100%-G38 -> 0.43478261 | H40: =100%-H38 -> 0 | I40: =100%-I38 -> 0.043478261 | J40: =100%-J38 -> 0.043478261 | K40: =100%-K38 -> 0.26086957 | M40: Unsuccessful | N40: =N37-N38 -> 8
M41: % Unsuccessful | N41: =N40/N37 -> 0.34782609 | V41: ='Class VII'!J7 -> 39.5

Sheet Class VI
A1: Alkhidmat School, Mannan & Qazi Campus, Hala
A2: Mid Term Examination 2025-26
A3: General Information - Grade VI | D3: Consolidated Result Sheet | L3: Aggregate
A4: Sr # | B4: Aghosh ID | C4: Name of Student | D4: Eng | E4: Urdu | F4: Science | G4: Maths | H4: Comp | I4: SS | J4: Islam | K4: Sindhi | L4: Total | M4: Secured Marks | N4: % | O4: Remarks
D5: 100 | E5: 100 | F5: 100 | G5: 100 | H5: Grades | I5: 50 | J5: 50 | K5: 50 | L5: =SUM(D5:K5) -> 550
A6: 1 | B6: AAH- 80 | C6: Farhan Ali | D6: 30 | E6: 50 | F6: 54 | G6: 57.5 | H6: B | I6: 0 | J6: 38.5 | K6: 34.5 | L6: 550 | M6: =SUM(D6:K6) -> 264.5 | N6: =M6/L15 -> 0.48090909 | O6: =IF(N6>=85%,"Outstanding",IF(N6>=80%,"Excellent",IF(N6>=70%,"Very Good",IF(N6>=60%,"Good",IF(N6>=50%,"Satisfactory",IF(N6>=40%,"Fair","Needs Attention")))))) -> Fair
A7: 2 | B7: AAH- 86 | C7: Asghar Ali | D7: 40 | E7: 48 | F7: 42 | G7: 31 | H7: B | I7: 23 | J7: 28.5 | K7: 20 | L7: 550 | M7: =SUM(D7:K7) -> 232.5 | N7: =M7/L5 -> 0.42272727 | O7: =IF(N7>=85%,"Outstanding",IF(N7>=80%,"Excellent",IF(N7>=70%,"Very Good",IF(N7>=60%,"Good",IF(N7>=50%,"Satisfactory",IF(N7>=40%,"Fair","Needs Attention")))))) -> Fair
A8: 3 | B8: AAH- 98 | C8: Abdul Samad | D8: 52 | E8: 81.5 | F8: 60.5 | G8: 38 | H8: C | I8: 29.5 | J8: 34 | K8: 34 | L8: 550 | M8: =SUM(D8:K8) -> 329.5 | N8: =M8/L7 -> 0.59909091 | O8: =IF(N8>=85%,"Outstanding",IF(N8>=80%,"Excellent",IF(N8>=70%,"Very Good",IF(N8>=60%,"Good",IF(N8>=50%,"Satisfactory",IF(N8>=40%,"Fair","Needs Attention")))))) -> Satisfactory
A9: 4 | B9: AAH- 108 | C9: Muhammad Yasir | D9: 19 | E9: 62 | F9: 26.5 | G9: 29 | H9: C | I9: 7 | J9: 35.5 | K9: 24 | L9: 550 | M9: =SUM(D9:K9) -> 203 | N9: =M9/L8 -> 0.36909091 | O9: =IF(N9>=85%,"Outstanding",IF(N9>=80%,"Excellent",IF(N9>=70%,"Very Good",IF(N9>=60%,"Good",IF(N9>=50%,"Satisfactory",IF(N9>=40%,"Fair","Needs Attention")))))) -> Needs Attention
A10: 5 | B10: AAH- 151 | C10: Hussain | D10: 27.5 | E10: 53.5 | F10: 42.5 | G10: 52 | H10: D | I10: 26.5 | J10: 30 | K10: 18 | L10: 550 | M10: =SUM(D10:K10) -> 250 | N10: =M10/L9 -> 0.45454545 | O10: =IF(N10>=85%,"Outstanding",IF(N10>=80%,"Excellent",IF(N10>=70%,"Very Good",IF(N10>=60%,"Good",IF(N10>=50%,"Satisfactory",IF(N10>=40%,"Fair","Needs Attention")))))) -> Fair
A11: 6 | B11: AAH- 154 | C11: Jawad Ahmed | D11: 72.5 | E11: 89.5 | F11: 70.5 | G11: 69 | H11: C | I11: 39 | J11: 47 | K11: 33 | L11: 550 | M11: =SUM(D11:K11) -> 420.5 | N11: =M11/'Class VII'!L8 -> 0.76454545 | O11: =IF(N11>=85%,"Outstanding",IF(N11>=80%,"Excellent",IF(N11>=70%,"Very Good",IF(N11>=60%,"Good",IF(N11>=50%,"Satisfactory",IF(N11>=40%,"Fair","Needs Attention")))))) -> Very Good
A12: 7 | B12: AAH- 155 | C12: Muzammil | D12: 57.5 | E12: 88.5 | F12: 70.5 | G12: 79 | H12: A | I12: 31 | J12: 49 | K12: 34.5 | L12: 550 | M12: =SUM(D12:K12) -> 410 | N12: =M12/L10 -> 0.74545455 | O12: =IF(N12>=85%,"Outstanding",IF(N12>=80%,"Excellent",IF(N12>=70%,"Very Good",IF(N12>=60%,"Good",IF(N12>=50%,"Satisfactory",IF(N12>=40%,"Fair","Needs Attention")))))) -> Very Good
A13: 8 | B13: AAH- 157 | C13: Abdul Ghafoor | D13: 80.5 | E13: 87 | F13: 95.5 | G13: 87 | H13: A | I13: 47 | J13: 47.5 | K13: 36.5 | L13: 550 | M13: =SUM(D13:K13) -> 481 | N13: =M13/L12 -> 0.87454545 | O13: =IF(N13>=85%,"Outstanding",IF(N13>=80%,"Excellent",IF(N13>=70%,"Very Good",IF(N13>=60%,"Good",IF(N13>=50%,"Satisfactory",IF(N13>=40%,"Fair","Needs Attention")))))) -> Outstanding
A14: 9 | B14: AAH- 215 | C14: Shahid Ali | D14: 99 | E14: 77 | F14: 78.5 | G14: 79 | H14: A | I14: 39.5 | J14: 47.5 | K14: 33 | L14: 550 | M14: =SUM(D14:K14) -> 453.5 | N14: =M14/L12 -> 0.82454545 | O14: =IF(N14>=85%,"Outstanding",IF(N14>=80%,"Excellent",IF(N14>=70%,"Very Good",IF(N14>=60%,"Good",IF(N14>=50%,"Satisfactory",IF(N14>=40%,"Fair","Needs Attention")))))) -> Excellent
A15: 10 | B15: AAH- 159 | C15: Adab Hussain | D15: 72 | E15: 92 | F15: 78.5 | G15: 79 | H15: A | I15: 39.5 | J15: 47.5 | K15: 33 | L15: 550 | M15: =SUM(D15:K15) -> 441.5 | N15: =M15/L13 -> 0.80272727 | O15: =IF(N15>=85%,"Outstanding",IF(N15>=80%,"Excellent",IF(N15>=70%,"Very Good",IF(N15>=60%,"Good",IF(N15>=50%,"Satisfactory",IF(N15>=40%,"Fair","Needs Attention")))))) -> Excellent
A16: ________________________ Principal | K16: ____________________ Class Teacher
C18: Subjects | D18: English | E18: Urdu | F18: Science | G18: Maths | H18: Comp | I18: SS | J18: Islamiat | K18: Sindhi | M18: Summary Grade VI
C19: Pass (>=40%) | D19: =9-D21 -> 6 | E19: =9-E21 -> 9 | F19: =9-F21 -> 8 | G19: =9-G21 -> 6 | H19: =9-H21 -> 9 | I19: =9-I21 -> 7 | J19: =9-J21 -> 9 | K19: =9-K21 -> 8 | M19: No. of Students | N19: 9
C20: Pass% | D20: =D19/9 -> 0.66666667 | E20: =E19/9 -> 1 | F20: =F19/9 -> 0.88888889 | G20: =G19/9 -> 0.66666667 | H20: =H19/9 -> 1 | I20: =I19/9 -> 0.77777778 | J20: =J19/9 -> 1 | K20: =K19/9 -> 0.88888889 | M20: Appeared | N20: 9
C21: Fail | D21: 3 | E21: 0 | F21: 1 | G21: 3 | H21: 0 | I21: 2 | J21: 0 | K21: 1 | M21: Pass | N21: 8
C22: Fail % | D22: =100%-D20 -> 0.33333333 | E22: =100%-E20 -> 0 | F22: =100%-F20 -> 0.11111111 | G22: =100%-G20 -> 0.33333333 | H22: =100%-H20 -> 0 | I22: =100%-I20 -> 0.22222222 | J22: =100%-J20 -> 0 | K22: =100%-K20 -> 0.11111111 | M22: % Pass | N22: =N21/N20 -> 0.88888889
M23: Unsuccessful | N23: =N20-N21 -> 1
M24: % Unsuccessful | N24: =N23/N20 -> 0.11111111

Sheet Class VII
A1: Alkhidmat School, Mannan & Qazi Campus, Hala
A2: Mid Term Examination 2025-26
A3: General Information - Grade VII | D3: Consolidated Result Sheet | L3: Aggregate
A4: Sr # | B4: Aghosh ID | C4: Name of Student | D4: Eng | E4: Urdu | F4: Science | G4: Maths | H4: Comp | I4: SS | J4: Islam | K4: Sindhi | L4: Total | M4: Secured Marks | N4: % | O4: Remarks
D5: 100 | E5: 100 | F5: 100 | G5: 100 | H5: Grades | I5: 50 | J5: 50 | K5: 50 | L5: =SUM(D5:K5) -> 550
A6: 1 | B6: AAH-006 | C6: Faizan Ali | D6: 90.5 | E6: 100 | F6: 97 | G6: 99 | H6: A | I6: 48.5 | J6: 50 | K6: 50 | L6: 550 | M6: =SUM(D6:K6) -> 535 | N6: =M6/'Class VIII'!L6 -> 0.97272727 | O6: =IF(N6>=85%,"Outstanding",IF(N6>=80%,"Excellent",IF(N6>=70%,"Very Good",IF(N6>=60%,"Good",IF(N6>=50%,"Satisfactory",IF(N6>=40%,"Fair","Needs Attention")))))) -> Outstanding
A7: 2 | B7: AAH-031 | C7: Arslan Ali | D7: 42.5 | E7: 68 | F7: 54 | G7: 41 | H7: B | I7: 24 | J7: 39.5 | K7: 43.5 | L7: 550 | M7: =SUM(D7:K7) -> 312.5 | N7: =M7/L5 -> 0.56818182 | O7: =IF(N7>=85%,"Outstanding",IF(N7>=80%,"Excellent",IF(N7>=70%,"Very Good",IF(N7>=60%,"Good",IF(N7>=50%,"Satisfactory",IF(N7>=40%,"Fair","Needs Attention")))))) -> Satisfactory
A8: 3 | B8: AAH-088 | C8: Farhan Ali | D8: 40 | E8: 40 | F8: 62 | G8: 27 | H8: E | I8: 33 | J8: 21.5 | K8: 12.5 | L8: 550 | M8: =SUM(D8:K8) -> 236 | N8: =M8/'Class VI'!L6 -> 0.42909091 | O8: =IF(N8>=85%,"Outstanding",IF(N8>=80%,"Excellent",IF(N8>=70%,"Very Good",IF(N8>=60%,"Good",IF(N8>=50%,"Satisfactory",IF(N8>=40%,"Fair","Needs Attention")))))) -> Fair
A9: 4 | B9: AAH-059 | C9: Abdul Qadeer | D9: 72.5 | E9: 83.5 | F9: 85 | G9: 51 | H9: B | I9: 31.5 | J9: 44.5 | K9: 43.5 | L9: 550 | M9: =SUM(D9:K9) -> 411.5 | N9: =M9/L7 -> 0.74818182 | O9: =IF(N9>=85%,"Outstanding",IF(N9>=80%,"Excellent",IF(N9>=70%,"Very Good",IF(N9>=60%,"Good",IF(N9>=50%,"Satisfactory",IF(N9>=40%,"Fair","Needs Attention")))))) -> Very Good
A10: 5 | B10: AAH-068 | C10: Ahmed | D10: 51 | E10: 75.5 | F10: 66 | G10: 60 | H10: B | I10: 29 | J10: 41 | K10: 44.5 | L10: 550 | M10: =SUM(D10:K10) -> 367 | N10: =M10/L9 -> 0.66727273 | O10: =IF(N10>=85%,"Outstanding",IF(N10>=80%,"Excellent",IF(N10>=70%,"Very Good",IF(N10>=60%,"Good",IF(N10>=50%,"Satisfactory",IF(N10>=40%,"Fair","Needs Attention")))))) -> Good
A11: 6 | B11: AAH-147 | C11: Balach Khan | D11: 86.5 | E11: 97.5 | F11: 98 | G11: 87 | H11: A | I11: 50 | J11: 50 | K11: 49.5 | L11: 550 | M11: =SUM(D11:K11) -> 518.5 | N11: =M11/'Class VIII'!L21 -> 0.94272727 | O11: =IF(N11>=85%,"Outstanding",IF(N11>=80%,"Excellent",IF(N11>=70%,"Very Good",IF(N11>=60%,"Good",IF(N11>=50%,"Satisfactory",IF(N11>=40%,"Fair","Needs Attention")))))) -> Outstanding
A12: 7 | B12: AAH-093 | C12: Farhan | D12: Absent | E12: Absent | F12: Absent | G12: Absent | H12: Absent | I12: Absent | J12: Absent | K12: Absent | L12: 550 | M12: =SUM(D12:K12) -> 0 | N12: =M12/'Class VIII'!L22 -> 0 | O12: =IF(N12>=85%,"Outstanding",IF(N12>=80%,"Excellent",IF(N12>=70%,"Very Good",IF(N12>=60%,"Good",IF(N12>=50%,"Satisfactory",IF(N12>=40%,"Fair","Needs Attention")))))) -> Needs Attention
A14: ________________________ Principal | K14: ____________________ Class Teacher
C16: Subjects | D16: English | E16: Urdu | F16: Science | G16: Maths | H16: Comp | I16: SS | J16: Islamiat | K16: Sindhi | M16: Summary Grad VII
C17: Pass (>=40%) | D17: =6-D19 -> 6 | E17: =6-E19 -> 6 | F17: =6-F19 -> 6 | G17: =6-G19 -> 5 | H17: =6-H19 -> 6 | I17: =6-I19 -> 6 | J17: =6-J19 -> 6 | K17: =6-K19 -> 5 | M17: No. of Students | N17: 7
C18: Pass% | D18: =D17/6 -> 1 | E18: =E17/6 -> 1 | F18: =F17/6 -> 1 | G18: =G17/6 -> 0.83333333 | H18: =H17/6 -> 1 | I18: =I17/6 -> 1 | J18: =J17/6 -> 1 | K18: =K17/6 -> 0.83333333 | M18: Appeared | N18: 6
C19: Fail | D19: 0 | E19: 0 | F19: 0 | G19: 1 | H19: 0 | I19: 0 | J19: 0 | K19: 1 | M19: Pass | N19: 6
C20: Fail % | D20: =100%-D18 -> 0 | E20: =100%-E18 -> 0 | F20: =100%-F18 -> 0 | G20: =100%-G18 -> 0.16666667 | H20: =100%-H18 -> 0 | I20: =100%-I18 -> 0 | J20: =100%-J18 -> 0 | K20: =100%-K18 -> 0.16666667 | M20: % Pass | N20: =N19/N18 -> 1
M21: Unsuccessful | N21: =N18-N19 -> 0
M22: % Unsuccessful | N22: =N21/N18 -> 0

Sheet Class VIII
A1: Alkhidmat School, Mannan & Qazi Campus, Hala
A2: Mid Term Examination 2025-26
A3: General Information - Grade VIII | D3: Consolidated Result Sheet | L3: Aggregate
A4: Sr # | B4: Aghosh ID | C4: Name of Student | D4: Eng | E4: Urdu | F4: Science | G4: Maths | H4: Comp | I4: S.S | J4: Islam | K4: Sindhi | L4: Total | M4: Secured Marks | N4: % | O4: Remarks
D5: 100 | E5: 100 | F5: 100 | G5: 100 | H5: Grades | I5: 50 | J5: 50 | K5: 50 | L5: =SUM(D5:K5) -> 550
A6: 1 | B6: AAH-001 | C6: Shan Ali | D6: 78 | E6: 95 | F6: 95 | G6: 89 | H6: A | I6: 47 | J6: 49 | K6: 48 | L6: 550 | M6: =SUM(D6:K6) -> 501 | N6: =M6/L5 -> 0.91090909 | O6: =IF(N6>=85%,"Outstanding",IF(N6>=80%,"Excellent",IF(N6>=70%,"Very Good",IF(N6>=60%,"Good",IF(N6>=50%,"Satisfactory",IF(N6>=40%,"Fair","Needs Attention")))))) -> Outstanding
A7: 2 | B7: AAH-008 | C7: Muzammil | D7: 56 | E7: 69.5 | F7: 84.5 | G7: 74.5 | H7: A | I7: 32 | J7: 36.5 | K7: 38.5 | L7: 550 | M7: =SUM(D7:K7) -> 391.5 | N7: =M7/'Class VII'!L6 -> 0.71181818 | O7: =IF(N7>=85%,"Outstanding",IF(N7>=80%,"Excellent",IF(N7>=70%,"Very Good",IF(N7>=60%,"Good",IF(N7>=50%,"Satisfactory",IF(N7>=40%,"Fair","Needs Attention")))))) -> Very Good
A8: 3 | B8: AAH-013 | C8: Muhammad Bilal | D8: 43 | E8: 44 | F8: 76 | G8: 53 | H8: C | I8: 29.5 | J8: 36 | K8: 34 | L8: 550 | M8: =SUM(D8:K8) -> 315.5 | N8: =M8/L7 -> 0.57363636 | O8: =IF(N8>=85%,"Outstanding",IF(N8>=80%,"Excellent",IF(N8>=70%,"Very Good",IF(N8>=60%,"Good",IF(N8>=50%,"Satisfactory",IF(N8>=40%,"Fair","Needs Attention")))))) -> Satisfactory
A9: 4 | B9: AAH-018 | C9: Asad | D9: 57 | E9: 72 | F9: 85 | G9: 71 | H9: B | I9: 26 | J9: 38.5 | K9: 41 | L9: 550 | M9: =SUM(D9:K9) -> 390.5 | N9: =M9/L8 -> 0.71 | O9: =IF(N9>=85%,"Outstanding",IF(N9>=80%,"Excellent",IF(N9>=70%,"Very Good",IF(N9>=60%,"Good",IF(N9>=50%,"Satisfactory",IF(N9>=40%,"Fair","Needs Attention")))))) -> Very Good
A10: 5 | B10: AAH-022 | C10: Abid Ali | D10: 90 | E10: 97 | F10: 96 | G10: 94 | H10: B | I10: 45 | J10: 50 | K10: 40 | L10: 550 | M10: =SUM(D10:K10) -> 512 | N10: =M10/L9 -> 0.93090909 | O10: =IF(N10>=85%,"Outstanding",IF(N10>=80%,"Excellent",IF(N10>=70%,"Very Good",IF(N10>=60%,"Good",IF(N10>=50%,"Satisfactory",IF(N10>=40%,"Fair","Needs Attention")))))) -> Outstanding
A11: 6 | B11: AAH-025 | C11: Ayaz Ali | D11: 69.5 | E11: 88 | F11: 94 | G11: 53 | H11: B | I11: 39 | J11: 48 | K11: 46.5 | L11: 550 | M11: =SUM(D11:K11) -> 438 | N11: =M11/L9 -> 0.79636364 | O11: =IF(N11>=85%,"Outstanding",IF(N11>=80%,"Excellent",IF(N11>=70%,"Very Good",IF(N11>=60%,"Good",IF(N11>=50%,"Satisfactory",IF(N11>=40%,"Fair","Needs Attention")))))) -> Very Good
A12: 7 | B12: AAH-026 | C12: Mujeeb ul Rehman | D12: 46.5 | E12: 58 | F12: 91 | G12: 53 | H12: B | I12: 23 | J12: 27 | K12: 30.5 | L12: 550 | M12: =SUM(D12:K12) -> 329 | N12: =M12/L11 -> 0.59818182 | O12: =IF(N12>=85%,"Outstanding",IF(N12>=80%,"Excellent",IF(N12>=70%,"Very Good",IF(N12>=60%,"Good",IF(N12>=50%,"Satisfactory",IF(N12>=40%,"Fair","Needs Attention")))))) -> Satisfactory
A13: 8 | B13: AAH-027 | C13: Sher Ali | D13: 46.5 | E13: 50.5 | F13: 75.5 | G13: 63.5 | H13: C | I13: 26.5 | J13: 36 | K13: 40.5 | L13: 550 | M13: =SUM(D13:K13) -> 339 | N13: =M13/L12 -> 0.61636364 | O13: =IF(N13>=85%,"Outstanding",IF(N13>=80%,"Excellent",IF(N13>=70%,"Very Good",IF(N13>=60%,"Good",IF(N13>=50%,"Satisfactory",IF(N13>=40%,"Fair","Needs Attention")))))) -> Good
A14: 9 | B14: AAH-033 | C14: Mushtaque Ali | D14: 51 | E14: 97 | F14: 67 | G14: 43.5 | H14: B | I14: 20.5 | J14: 50 | K14: 50 | L14: 550 | M14: =SUM(D14:K14) -> 379 | N14: =M14/L13 -> 0.68909091 | O14: =IF(N14>=85%,"Outstanding",IF(N14>=80%,"Excellent",IF(N14>=70%,"Very Good",IF(N14>=60%,"Good",IF(N14>=50%,"Satisfactory",IF(N14>=40%,"Fair","Needs Attention")))))) -> Good
A15: 10 | B15: AAH-034 | C15: Asad Ali | D15: 31 | E15: 53 | F15: 47 | G15: 48 | H15: C | I15: 16 | J15: 38 | K15: 46.5 | L15: 550 | M15: =SUM(D15:K15) -> 279.5 | N15: =M15/L14 -> 0.50818182 | O15: =IF(N15>=85%,"Outstanding",IF(N15>=80%,"Excellent",IF(N15>=70%,"Very Good",IF(N15>=60%,"Good",IF(N15>=50%,"Satisfactory",IF(N15>=40%,"Fair","Needs Attention")))))) -> Satisfactory
A16: 11 | B16: AAH-041 | C16: Noman Ali | D16: 40 | E16: 42 | F16: 42 | G16: 40 | H16: C | I16: 26 | J16: 24.5 | K16: 22 | L16: 550 | M16: =SUM(D16:K16) -> 236.5 | N16: =M16/'Class VII'!L7 -> 0.43 | O16: =IF(N16>=85%,"Outstanding",IF(N16>=80%,"Excellent",IF(N16>=70%,"Very Good",IF(N16>=60%,"Good",IF(N16>=50%,"Satisfactory",IF(N16>=40%,"Fair","Needs Attention")))))) -> Fair
A17: 12 | B17: AAH-046 | C17: Hasnain Ali | D17: 36 | E17: 57.5 | F17: 68.5 | G17: 56 | H17: C | I17: 28.5 | J17: 30 | K17: 37.5 | L17: 550 | M17: =SUM(D17:K17) -> 314 | N17: =M17/L15 -> 0.57090909 | O17: =IF(N17>=85%,"Outstanding",IF(N17>=80%,"Excellent",IF(N17>=70%,"Very Good",IF(N17>=60%,"Good",IF(N17>=50%,"Satisfactory",IF(N17>=40%,"Fair","Needs Attention")))))) -> Satisfactory
A18: 13 | B18: AAH-054 | C18: Muhammad Mohsin | D18: 46 | E18: 81.5 | F18: 74.5 | G18: 46.5 | H18: B | I18: 25 | J18: 45.5 | K18: 47.5 | L18: 550 | M18: =SUM(D18:K18) -> 366.5 | N18: =M18/L17 -> 0.66636364 | O18: =IF(N18>=85%,"Outstanding",IF(N18>=80%,"Excellent",IF(N18>=70%,"Very Good",IF(N18>=60%,"Good",IF(N18>=50%,"Satisfactory",IF(N18>=40%,"Fair","Needs Attention")))))) -> Good
A19: 14 | B19: AAH-056 | C19: Javed Ali | D19: 26 | E19: 33.5 | F19: 42.5 | G19: 52 | H19: C | I19: 21 | J19: 26.5 | K19: 38 | L19: 550 | M19: =SUM(D19:K19) -> 239.5 | N19: =M19/L18 -> 0.43545455 | O19: =IF(N19>=85%,"Outstanding",IF(N19>=80%,"Excellent",IF(N19>=70%,"Very Good",IF(N19>=60%,"Good",IF(N19>=50%,"Satisfactory",IF(N19>=40%,"Fair","Needs Attention")))))) -> Fair
A20: 15 | B20: AAH-069 | C20: Abdul Samad | D20: 44 | E20: 52.5 | F20: 67 | G20: 64 | H20: C | I20: 20 | J20: 39.5 | K20: 33 | L20: 550 | M20: =SUM(D20:K20) -> 320 | N20: =M20/L19 -> 0.58181818 | O20: =IF(N20>=85%,"Outstanding",IF(N20>=80%,"Excellent",IF(N20>=70%,"Very Good",IF(N20>=60%,"Good",IF(N20>=50%,"Satisfactory",IF(N20>=40%,"Fair","Needs Attention")))))) -> Satisfactory
A21: 16 | B21: AAH-070 | C21: Aasim | D21: Absent | E21: Absent | F21: 73 | G21: 65 | H21: A | I21: Absent | J21: Absent | K21: Absent | L21: 550 | M21: =SUM(D21:K21) -> 138 | N21: =M21/L20 -> 0.25090909 | O21: =IF(N21>=85%,"Outstanding",IF(N21>=80%,"Excellent",IF(N21>=70%,"Very Good",IF(N21>=60%,"Good",IF(N21>=50%,"Satisfactory",IF(N21>=40%,"Fair","Needs Attention")))))) -> Needs Attention
A22: 17 | B22: AAH- 73 | C22: Zakir Ali | D22: 50.5 | E22: 70 | F22: 59.5 | G22: 86 | H22: A | I22: 34 | J22: 46.5 | K22: 37.5 | L22: 550 | M22: =SUM(D22:K22) -> 384 | N22: =M22/'Class VII'!L10 -> 0.69818182 | O22: =IF(N22>=85%,"Outstanding",IF(N22>=80%,"Excellent",IF(N22>=70%,"Very Good",IF(N22>=60%,"Good",IF(N22>=50%,"Satisfactory",IF(N22>=40%,"Fair","Needs Attention")))))) -> Good
A23: 18 | B23: AAH-148 | C23: Israr Ahmed | D23: 93.5 | E23: 99.5 | F23: 100 | G23: 92 | H23: A | I23: 98 | J23: 50 | K23: 45 | L23: 650 | M23: =SUM(D23:K23) -> 578 | N23: =M23/'Class IX'!L12 -> 0.88923077 | O23: =IF(N23>=85%,"Outstanding",IF(N23>=80%,"Excellent",IF(N23>=70%,"Very Good",IF(N23>=60%,"Good",IF(N23>=50%,"Satisfactory",IF(N23>=40%,"Fair","Needs Attention")))))) -> Outstanding
A24: 19 | B24: AAH-156 | C24: Ijaz Ahmed | D24: 64 | E24: 80 | F24: 85 | G24: 56 | H24: C | I24: 36.5 | J24: 46 | K24: 48 | L24: 550 | M24: =SUM(D24:K24) -> 415.5 | N24: =M24/'Class VII'!L11 -> 0.75545455 | O24: =IF(N24>=85%,"Outstanding",IF(N24>=80%,"Excellent",IF(N24>=70%,"Very Good",IF(N24>=60%,"Good",IF(N24>=50%,"Satisfactory",IF(N24>=40%,"Fair","Needs Attention")))))) -> Very Good
A26: ________________________ Principal | K26: ____________________ Class Teacher
A28: ________________________ Principal | K28: ____________________ Class Teacher
C29: Subjects | D29: English | E29: Urdu | F29: Science | G29: Maths | H29: Comp | I29: SS | J29: Islamiat | K29: Sindhi | M29: Summary Grade VIII
C30: Pass (>=40%) | D30: =19-D32 -> 16 | E30: =19-E32 -> 18 | F30: =19-F32 -> 19 | G30: =19-G32 -> 19 | H30: =19-H32 -> 18 | I30: =19-I32 -> 18 | J30: =19-J32 -> 19 | K30: =19-K32 -> 19 | M30: No. of Students | N30: 19
C31: Pass% | D31: =D30/19 -> 0.84210526 | E31: =E30/19 -> 0.94736842 | F31: =F30/19 -> 1 | G31: =G30/19 -> 1 | H31: =H30/19 -> 0.94736842 | I31: =I30/19 -> 0.94736842 | J31: =J30/19 -> 1 | K31: =K30/19 -> 1 | M31: Appeared | N31: 19
C32: Fail | D32: 3 | E32: 1 | F32: 0 | G32: 0 | H32: 1 | I32: 1 | J32: 0 | K32: 0 | M32: Pass | N32: 18
C33: Fail % | D33: =100%-D31 -> 0.15789474 | E33: =100%-E31 -> 0.052631579 | F33: =100%-F31 -> 0 | G33: =100%-G31 -> 0 | H33: =100%-H31 -> 0.052631579 | I33: =100%-I31 -> 0.052631579 | J33: =100%-J31 -> 0 | K33: =100%-K31 -> 0 | M33: % Pass | N33: =N32/N31 -> 0.94736842
M34: Unsuccessful | N34: =N31-N32 -> 1
M35: % Unsuccessful | N35: =N34/N31 -> 0.052631579

Sheet Class IX
A1: Alkhidmat School, Mannan & Qazi Campus, Hala
A2: Mid Term Examination 2025-26
A3: General Information - Grade IX | D3: Consolidated Result Sheet | L3: Aggregate
A4: Sr # | B4: Aghosh ID | C4: Name of Student | D4: Eng | E4: Urdu | F4: Maths | G4: Bio | H4: Phy | I4: Che | J4: Comp | K4: Islam | L4: Total | M4: Secured Marks | N4: % | O4: Remarks
D5: 100 | E5: 100 | F5: 100 | G5: 100 | H5: 100 | I5: 100 | J5: Grades | K5: 50 | L5: =SUM(D5:K5) -> 650
